Traceback (most recent call last):
  File "/home/yblee/workspace/tdc/.venv/lib/python3.10/site-packages/jupyter_cache/executors/utils.py", line 58, in single_nb_execution
    executenb(
  File "/home/yblee/workspace/tdc/.venv/lib/python3.10/site-packages/nbclient/client.py", line 1305, in execute
    return NotebookClient(nb=nb, resources=resources, km=km, **kwargs).execute()
  File "/home/yblee/workspace/tdc/.venv/lib/python3.10/site-packages/jupyter_core/utils/__init__.py", line 166, in wrapped
    return loop.run_until_complete(inner)
  File "/usr/lib/python3.10/asyncio/base_events.py", line 646, in run_until_complete
    return future.result()
  File "/home/yblee/workspace/tdc/.venv/lib/python3.10/site-packages/nbclient/client.py", line 705, in async_execute
    await self.async_execute_cell(
  File "/home/yblee/workspace/tdc/.venv/lib/python3.10/site-packages/nbclient/client.py", line 1058, in async_execute_cell
    await self._check_raise_for_error(cell, cell_index, exec_reply)
  File "/home/yblee/workspace/tdc/.venv/lib/python3.10/site-packages/nbclient/client.py", line 914, in _check_raise_for_error
    raise CellExecutionError.from_cell_and_msg(cell, exec_reply_content)
nbclient.exceptions.CellExecutionError: An error occurred while executing the following cell:
------------------
from myst_nb import glue
import pandas as pd
df = pd.read_pickle('./history/history.pickle')
df = df.sort_value(['date'], ascending=False)
df.head()
------------------


[0;31m---------------------------------------------------------------------------[0m
[0;31mAttributeError[0m                            Traceback (most recent call last)
[0;32m/tmp/ipykernel_21273/8789794.py[0m in [0;36m?[0;34m()[0m
[1;32m      1[0m [0;32mfrom[0m [0mmyst_nb[0m [0;32mimport[0m [0mglue[0m[0;34m[0m[0;34m[0m[0m
[1;32m      2[0m [0;32mimport[0m [0mpandas[0m [0;32mas[0m [0mpd[0m[0;34m[0m[0;34m[0m[0m
[1;32m      3[0m [0mdf[0m [0;34m=[0m [0mpd[0m[0;34m.[0m[0mread_pickle[0m[0;34m([0m[0;34m'./history/history.pickle'[0m[0;34m)[0m[0;34m[0m[0;34m[0m[0m
[0;32m----> 4[0;31m [0mdf[0m [0;34m=[0m [0mdf[0m[0;34m.[0m[0msort_value[0m[0;34m([0m[0;34m[[0m[0;34m'date'[0m[0;34m][0m[0;34m,[0m [0mascending[0m[0;34m=[0m[0;32mFalse[0m[0;34m)[0m[0;34m[0m[0;34m[0m[0m
[0m[1;32m      5[0m [0mdf[0m[0;34m.[0m[0mhead[0m[0;34m([0m[0;34m)[0m[0;34m[0m[0;34m[0m[0m

[0;32m~/workspace/tdc/.venv/lib/python3.10/site-packages/pandas/core/generic.py[0m in [0;36m?[0;34m(self, name)[0m
[1;32m   5985[0m             [0;32mand[0m [0mname[0m [0;32mnot[0m [0;32min[0m [0mself[0m[0;34m.[0m[0m_accessors[0m[0;34m[0m[0;34m[0m[0m
[1;32m   5986[0m             [0;32mand[0m [0mself[0m[0;34m.[0m[0m_info_axis[0m[0;34m.[0m[0m_can_hold_identifiers_and_holds_name[0m[0;34m([0m[0mname[0m[0;34m)[0m[0;34m[0m[0;34m[0m[0m
[1;32m   5987[0m         ):
[1;32m   5988[0m             [0;32mreturn[0m [0mself[0m[0;34m[[0m[0mname[0m[0;34m][0m[0;34m[0m[0;34m[0m[0m
[0;32m-> 5989[0;31m         [0;32mreturn[0m [0mobject[0m[0;34m.[0m[0m__getattribute__[0m[0;34m([0m[0mself[0m[0;34m,[0m [0mname[0m[0;34m)[0m[0;34m[0m[0;34m[0m[0m
[0m
[0;31mAttributeError[0m: 'DataFrame' object has no attribute 'sort_value'

